2020-10-10 16:49:58,018 -  nornir.core -     INFO -        run() - Running task 'get_bgp_peers' with args {} on 6 hosts
2020-10-10 17:38:40,776 -  nornir.core -  WARNING -        run() - Task 'netmiko_send_command' has not been run – 0 hosts selected
2020-10-10 17:38:40,830 -  nornir.core -  WARNING -        run() - Task 'napalm_get' has not been run – 0 hosts selected
2020-10-10 17:38:40,878 -  nornir.core -     INFO -        run() - Running task 'napalm_get' with args {'getters': ['facts'], 'severity_level': 20} on 1 hosts
2020-10-10 17:38:54,543 -  nornir.core -     INFO -        run() - Running task 'collect_xr_multiple' with args {'severity_level': 20} on 1 hosts
2020-10-10 17:39:05,634 -  nornir.core -     INFO -        run() - Running task 'napalm_get' with args {'getters': ['facts'], 'severity_level': 20} on 7 hosts
2020-12-05 18:45:47,028 -  nornir.core -     INFO -        run() - Running task 'get_bgp_peers' with args {} on 7 hosts
2020-12-05 18:49:57,548 -  nornir.core -     INFO -        run() - Running task 'netflow_configuration' with args {} on 7 hosts
2020-12-05 18:50:08,240 -  nornir.core -  WARNING -        run() - Task 'xr_multiple' has not been run – 0 hosts selected
2020-12-05 18:50:08,325 -  nornir.core -     INFO -        run() - Running task 'napalm_get' with args {'getters': ['optics', 'interfaces'], 'severity_level': 20} on 7 hosts
2020-12-05 18:50:39,003 -  nornir.core -  WARNING -        run() - Task 'netmiko_send_command' has not been run – 0 hosts selected
2020-12-05 18:50:39,080 -  nornir.core -     INFO -        run() - Running task 'get_cards_jnp' with args {'severity_level': 20} on 7 hosts
2020-12-05 18:50:39,198 - nornir.core.task -    ERROR -      start() - Host 'ke-p6-nbi': task 'get_cards_jnp' failed with traceback:
Traceback (most recent call last):
  File "/home/lab/lnetd_env/lib/python3.7/site-packages/jnpr/junos/device.py", line 1360, in open
    "use_filter": self._use_filter,
  File "/home/lab/lnetd_env/lib/python3.7/site-packages/ncclient/manager.py", line 168, in connect
    return connect_ssh(*args, **kwds)
  File "/home/lab/lnetd_env/lib/python3.7/site-packages/ncclient/manager.py", line 135, in connect_ssh
    session.connect(*args, **kwds)
  File "/home/lab/lnetd_env/lib/python3.7/site-packages/ncclient/transport/ssh.py", line 275, in connect
    for res in socket.getaddrinfo(host, port, socket.AF_UNSPEC, socket.SOCK_STREAM):
  File "/usr/lib/python3.7/socket.py", line 752, in getaddrinfo
    for res in _socket.getaddrinfo(host, port, family, type, proto, flags):
socket.gaierror: [Errno -3] Temporary failure in name resolution

During handling of the above exception, another exception occurred:

Traceback (most recent call last):
  File "/opt/lnetd/inputs/nornir/mutils.py", line 55, in get_cards_jnp
    dev.open()
  File "/home/lab/lnetd_env/lib/python3.7/site-packages/jnpr/junos/device.py", line 1396, in open
    raise EzErrors.ConnectUnknownHostError(self)
jnpr.junos.exception.ConnectUnknownHostError: ConnectUnknownHostError(ke-p6-nbi)

During handling of the above exception, another exception occurred:

Traceback (most recent call last):
  File "/home/lab/lnetd_env/lib/python3.7/site-packages/nornir/core/task.py", line 98, in start
    r = self.task(self, **self.params)
  File "/opt/lnetd/inputs/nornir/mutils.py", line 74, in get_cards_jnp
    raise Exception
Exception

2020-12-05 18:50:39,248 - nornir.core.task -    ERROR -      start() - Host 'fr-p7-mrs': task 'get_cards_jnp' failed with traceback:
Traceback (most recent call last):
  File "/home/lab/lnetd_env/lib/python3.7/site-packages/jnpr/junos/device.py", line 1360, in open
    "use_filter": self._use_filter,
  File "/home/lab/lnetd_env/lib/python3.7/site-packages/ncclient/manager.py", line 168, in connect
    return connect_ssh(*args, **kwds)
  File "/home/lab/lnetd_env/lib/python3.7/site-packages/ncclient/manager.py", line 135, in connect_ssh
    session.connect(*args, **kwds)
  File "/home/lab/lnetd_env/lib/python3.7/site-packages/ncclient/transport/ssh.py", line 275, in connect
    for res in socket.getaddrinfo(host, port, socket.AF_UNSPEC, socket.SOCK_STREAM):
  File "/usr/lib/python3.7/socket.py", line 752, in getaddrinfo
    for res in _socket.getaddrinfo(host, port, family, type, proto, flags):
socket.gaierror: [Errno -3] Temporary failure in name resolution

During handling of the above exception, another exception occurred:

Traceback (most recent call last):
  File "/opt/lnetd/inputs/nornir/mutils.py", line 55, in get_cards_jnp
    dev.open()
  File "/home/lab/lnetd_env/lib/python3.7/site-packages/jnpr/junos/device.py", line 1396, in open
    raise EzErrors.ConnectUnknownHostError(self)
jnpr.junos.exception.ConnectUnknownHostError: ConnectUnknownHostError(fr-p7-mrs)

During handling of the above exception, another exception occurred:

Traceback (most recent call last):
  File "/home/lab/lnetd_env/lib/python3.7/site-packages/nornir/core/task.py", line 98, in start
    r = self.task(self, **self.params)
  File "/opt/lnetd/inputs/nornir/mutils.py", line 74, in get_cards_jnp
    raise Exception
Exception

2020-12-05 18:50:39,249 - nornir.core.task -    ERROR -      start() - Host 'gb-pe8-lon': task 'get_cards_jnp' failed with traceback:
Traceback (most recent call last):
  File "/home/lab/lnetd_env/lib/python3.7/site-packages/jnpr/junos/device.py", line 1360, in open
    "use_filter": self._use_filter,
  File "/home/lab/lnetd_env/lib/python3.7/site-packages/ncclient/manager.py", line 168, in connect
    return connect_ssh(*args, **kwds)
  File "/home/lab/lnetd_env/lib/python3.7/site-packages/ncclient/manager.py", line 135, in connect_ssh
    session.connect(*args, **kwds)
  File "/home/lab/lnetd_env/lib/python3.7/site-packages/ncclient/transport/ssh.py", line 275, in connect
    for res in socket.getaddrinfo(host, port, socket.AF_UNSPEC, socket.SOCK_STREAM):
  File "/usr/lib/python3.7/socket.py", line 752, in getaddrinfo
    for res in _socket.getaddrinfo(host, port, family, type, proto, flags):
socket.gaierror: [Errno -3] Temporary failure in name resolution

During handling of the above exception, another exception occurred:

Traceback (most recent call last):
  File "/opt/lnetd/inputs/nornir/mutils.py", line 55, in get_cards_jnp
    dev.open()
  File "/home/lab/lnetd_env/lib/python3.7/site-packages/jnpr/junos/device.py", line 1396, in open
    raise EzErrors.ConnectUnknownHostError(self)
jnpr.junos.exception.ConnectUnknownHostError: ConnectUnknownHostError(gb-pe8-lon)

During handling of the above exception, another exception occurred:

Traceback (most recent call last):
  File "/home/lab/lnetd_env/lib/python3.7/site-packages/nornir/core/task.py", line 98, in start
    r = self.task(self, **self.params)
  File "/opt/lnetd/inputs/nornir/mutils.py", line 74, in get_cards_jnp
    raise Exception
Exception

2020-12-05 18:50:39,288 - nornir.core.task -    ERROR -      start() - Host 'gb-pe5-lon': task 'get_cards_jnp' failed with traceback:
Traceback (most recent call last):
  File "/home/lab/lnetd_env/lib/python3.7/site-packages/jnpr/junos/device.py", line 1360, in open
    "use_filter": self._use_filter,
  File "/home/lab/lnetd_env/lib/python3.7/site-packages/ncclient/manager.py", line 168, in connect
    return connect_ssh(*args, **kwds)
  File "/home/lab/lnetd_env/lib/python3.7/site-packages/ncclient/manager.py", line 135, in connect_ssh
    session.connect(*args, **kwds)
  File "/home/lab/lnetd_env/lib/python3.7/site-packages/ncclient/transport/ssh.py", line 275, in connect
    for res in socket.getaddrinfo(host, port, socket.AF_UNSPEC, socket.SOCK_STREAM):
  File "/usr/lib/python3.7/socket.py", line 752, in getaddrinfo
    for res in _socket.getaddrinfo(host, port, family, type, proto, flags):
socket.gaierror: [Errno -3] Temporary failure in name resolution

During handling of the above exception, another exception occurred:

Traceback (most recent call last):
  File "/opt/lnetd/inputs/nornir/mutils.py", line 55, in get_cards_jnp
    dev.open()
  File "/home/lab/lnetd_env/lib/python3.7/site-packages/jnpr/junos/device.py", line 1396, in open
    raise EzErrors.ConnectUnknownHostError(self)
jnpr.junos.exception.ConnectUnknownHostError: ConnectUnknownHostError(gb-pe5-lon)

During handling of the above exception, another exception occurred:

Traceback (most recent call last):
  File "/home/lab/lnetd_env/lib/python3.7/site-packages/nornir/core/task.py", line 98, in start
    r = self.task(self, **self.params)
  File "/opt/lnetd/inputs/nornir/mutils.py", line 74, in get_cards_jnp
    raise Exception
Exception

2020-12-05 18:50:39,289 - nornir.core.task -    ERROR -      start() - Host 'gb-p10-lon': task 'get_cards_jnp' failed with traceback:
Traceback (most recent call last):
  File "/home/lab/lnetd_env/lib/python3.7/site-packages/jnpr/junos/device.py", line 1360, in open
    "use_filter": self._use_filter,
  File "/home/lab/lnetd_env/lib/python3.7/site-packages/ncclient/manager.py", line 168, in connect
    return connect_ssh(*args, **kwds)
  File "/home/lab/lnetd_env/lib/python3.7/site-packages/ncclient/manager.py", line 135, in connect_ssh
    session.connect(*args, **kwds)
  File "/home/lab/lnetd_env/lib/python3.7/site-packages/ncclient/transport/ssh.py", line 275, in connect
    for res in socket.getaddrinfo(host, port, socket.AF_UNSPEC, socket.SOCK_STREAM):
  File "/usr/lib/python3.7/socket.py", line 752, in getaddrinfo
    for res in _socket.getaddrinfo(host, port, family, type, proto, flags):
socket.gaierror: [Errno -3] Temporary failure in name resolution

During handling of the above exception, another exception occurred:

Traceback (most recent call last):
  File "/opt/lnetd/inputs/nornir/mutils.py", line 55, in get_cards_jnp
    dev.open()
  File "/home/lab/lnetd_env/lib/python3.7/site-packages/jnpr/junos/device.py", line 1396, in open
    raise EzErrors.ConnectUnknownHostError(self)
jnpr.junos.exception.ConnectUnknownHostError: ConnectUnknownHostError(gb-p10-lon)

During handling of the above exception, another exception occurred:

Traceback (most recent call last):
  File "/home/lab/lnetd_env/lib/python3.7/site-packages/nornir/core/task.py", line 98, in start
    r = self.task(self, **self.params)
  File "/opt/lnetd/inputs/nornir/mutils.py", line 74, in get_cards_jnp
    raise Exception
Exception

2020-12-05 18:50:39,318 - nornir.core.task -    ERROR -      start() - Host 'ke-pe3-nbi': task 'get_cards_jnp' failed with traceback:
Traceback (most recent call last):
  File "/home/lab/lnetd_env/lib/python3.7/site-packages/jnpr/junos/device.py", line 1360, in open
    "use_filter": self._use_filter,
  File "/home/lab/lnetd_env/lib/python3.7/site-packages/ncclient/manager.py", line 168, in connect
    return connect_ssh(*args, **kwds)
  File "/home/lab/lnetd_env/lib/python3.7/site-packages/ncclient/manager.py", line 135, in connect_ssh
    session.connect(*args, **kwds)
  File "/home/lab/lnetd_env/lib/python3.7/site-packages/ncclient/transport/ssh.py", line 275, in connect
    for res in socket.getaddrinfo(host, port, socket.AF_UNSPEC, socket.SOCK_STREAM):
  File "/usr/lib/python3.7/socket.py", line 752, in getaddrinfo
    for res in _socket.getaddrinfo(host, port, family, type, proto, flags):
socket.gaierror: [Errno -3] Temporary failure in name resolution

During handling of the above exception, another exception occurred:

Traceback (most recent call last):
  File "/opt/lnetd/inputs/nornir/mutils.py", line 55, in get_cards_jnp
    dev.open()
  File "/home/lab/lnetd_env/lib/python3.7/site-packages/jnpr/junos/device.py", line 1396, in open
    raise EzErrors.ConnectUnknownHostError(self)
jnpr.junos.exception.ConnectUnknownHostError: ConnectUnknownHostError(ke-pe3-nbi)

During handling of the above exception, another exception occurred:

Traceback (most recent call last):
  File "/home/lab/lnetd_env/lib/python3.7/site-packages/nornir/core/task.py", line 98, in start
    r = self.task(self, **self.params)
  File "/opt/lnetd/inputs/nornir/mutils.py", line 74, in get_cards_jnp
    raise Exception
Exception

2020-12-05 18:50:39,324 - nornir.core.task -    ERROR -      start() - Host 'ke-pe2-nbi': task 'get_cards_jnp' failed with traceback:
Traceback (most recent call last):
  File "/home/lab/lnetd_env/lib/python3.7/site-packages/jnpr/junos/device.py", line 1360, in open
    "use_filter": self._use_filter,
  File "/home/lab/lnetd_env/lib/python3.7/site-packages/ncclient/manager.py", line 168, in connect
    return connect_ssh(*args, **kwds)
  File "/home/lab/lnetd_env/lib/python3.7/site-packages/ncclient/manager.py", line 135, in connect_ssh
    session.connect(*args, **kwds)
  File "/home/lab/lnetd_env/lib/python3.7/site-packages/ncclient/transport/ssh.py", line 275, in connect
    for res in socket.getaddrinfo(host, port, socket.AF_UNSPEC, socket.SOCK_STREAM):
  File "/usr/lib/python3.7/socket.py", line 752, in getaddrinfo
    for res in _socket.getaddrinfo(host, port, family, type, proto, flags):
socket.gaierror: [Errno -3] Temporary failure in name resolution

During handling of the above exception, another exception occurred:

Traceback (most recent call last):
  File "/opt/lnetd/inputs/nornir/mutils.py", line 55, in get_cards_jnp
    dev.open()
  File "/home/lab/lnetd_env/lib/python3.7/site-packages/jnpr/junos/device.py", line 1396, in open
    raise EzErrors.ConnectUnknownHostError(self)
jnpr.junos.exception.ConnectUnknownHostError: ConnectUnknownHostError(ke-pe2-nbi)

During handling of the above exception, another exception occurred:

Traceback (most recent call last):
  File "/home/lab/lnetd_env/lib/python3.7/site-packages/nornir/core/task.py", line 98, in start
    r = self.task(self, **self.params)
  File "/opt/lnetd/inputs/nornir/mutils.py", line 74, in get_cards_jnp
    raise Exception
Exception

2020-12-05 18:50:39,447 -  nornir.core -  WARNING -        run() - Task 'huawei_multiple' has not been run – 0 hosts selected
2020-12-05 20:08:04,489 -  nornir.core -     INFO -        run() - Running task 'netflow_configuration' with args {} on 7 hosts
2020-12-05 20:08:34,194 -  nornir.core -  WARNING -        run() - Task 'xr_multiple' has not been run – 0 hosts selected
2020-12-05 20:08:34,250 -  nornir.core -     INFO -        run() - Running task 'napalm_get' with args {'getters': ['optics', 'interfaces'], 'severity_level': 20} on 7 hosts
2020-12-05 20:09:07,424 -  nornir.core -  WARNING -        run() - Task 'netmiko_send_command' has not been run – 0 hosts selected
2020-12-05 20:09:07,493 -  nornir.core -     INFO -        run() - Running task 'get_cards_jnp' with args {'severity_level': 20} on 7 hosts
2020-12-05 20:09:07,675 - nornir.core.task -    ERROR -      start() - Host 'gb-pe5-lon': task 'get_cards_jnp' failed with traceback:
Traceback (most recent call last):
  File "/home/lab/lnetd_env/lib/python3.7/site-packages/jnpr/junos/device.py", line 1360, in open
    "use_filter": self._use_filter,
  File "/home/lab/lnetd_env/lib/python3.7/site-packages/ncclient/manager.py", line 168, in connect
    return connect_ssh(*args, **kwds)
  File "/home/lab/lnetd_env/lib/python3.7/site-packages/ncclient/manager.py", line 135, in connect_ssh
    session.connect(*args, **kwds)
  File "/home/lab/lnetd_env/lib/python3.7/site-packages/ncclient/transport/ssh.py", line 275, in connect
    for res in socket.getaddrinfo(host, port, socket.AF_UNSPEC, socket.SOCK_STREAM):
  File "/usr/lib/python3.7/socket.py", line 752, in getaddrinfo
    for res in _socket.getaddrinfo(host, port, family, type, proto, flags):
socket.gaierror: [Errno -3] Temporary failure in name resolution

During handling of the above exception, another exception occurred:

Traceback (most recent call last):
  File "/opt/lnetd/inputs/nornir/mutils.py", line 55, in get_cards_jnp
    dev.open()
  File "/home/lab/lnetd_env/lib/python3.7/site-packages/jnpr/junos/device.py", line 1396, in open
    raise EzErrors.ConnectUnknownHostError(self)
jnpr.junos.exception.ConnectUnknownHostError: ConnectUnknownHostError(gb-pe5-lon)

During handling of the above exception, another exception occurred:

Traceback (most recent call last):
  File "/home/lab/lnetd_env/lib/python3.7/site-packages/nornir/core/task.py", line 98, in start
    r = self.task(self, **self.params)
  File "/opt/lnetd/inputs/nornir/mutils.py", line 74, in get_cards_jnp
    raise Exception
Exception

2020-12-05 20:09:07,676 - nornir.core.task -    ERROR -      start() - Host 'gb-pe8-lon': task 'get_cards_jnp' failed with traceback:
Traceback (most recent call last):
  File "/home/lab/lnetd_env/lib/python3.7/site-packages/jnpr/junos/device.py", line 1360, in open
    "use_filter": self._use_filter,
  File "/home/lab/lnetd_env/lib/python3.7/site-packages/ncclient/manager.py", line 168, in connect
    return connect_ssh(*args, **kwds)
  File "/home/lab/lnetd_env/lib/python3.7/site-packages/ncclient/manager.py", line 135, in connect_ssh
    session.connect(*args, **kwds)
  File "/home/lab/lnetd_env/lib/python3.7/site-packages/ncclient/transport/ssh.py", line 275, in connect
    for res in socket.getaddrinfo(host, port, socket.AF_UNSPEC, socket.SOCK_STREAM):
  File "/usr/lib/python3.7/socket.py", line 752, in getaddrinfo
    for res in _socket.getaddrinfo(host, port, family, type, proto, flags):
socket.gaierror: [Errno -3] Temporary failure in name resolution

During handling of the above exception, another exception occurred:

Traceback (most recent call last):
  File "/opt/lnetd/inputs/nornir/mutils.py", line 55, in get_cards_jnp
    dev.open()
  File "/home/lab/lnetd_env/lib/python3.7/site-packages/jnpr/junos/device.py", line 1396, in open
    raise EzErrors.ConnectUnknownHostError(self)
jnpr.junos.exception.ConnectUnknownHostError: ConnectUnknownHostError(gb-pe8-lon)

During handling of the above exception, another exception occurred:

Traceback (most recent call last):
  File "/home/lab/lnetd_env/lib/python3.7/site-packages/nornir/core/task.py", line 98, in start
    r = self.task(self, **self.params)
  File "/opt/lnetd/inputs/nornir/mutils.py", line 74, in get_cards_jnp
    raise Exception
Exception

2020-12-05 20:09:07,677 - nornir.core.task -    ERROR -      start() - Host 'ke-p6-nbi': task 'get_cards_jnp' failed with traceback:
Traceback (most recent call last):
  File "/home/lab/lnetd_env/lib/python3.7/site-packages/jnpr/junos/device.py", line 1360, in open
    "use_filter": self._use_filter,
  File "/home/lab/lnetd_env/lib/python3.7/site-packages/ncclient/manager.py", line 168, in connect
    return connect_ssh(*args, **kwds)
  File "/home/lab/lnetd_env/lib/python3.7/site-packages/ncclient/manager.py", line 135, in connect_ssh
    session.connect(*args, **kwds)
  File "/home/lab/lnetd_env/lib/python3.7/site-packages/ncclient/transport/ssh.py", line 275, in connect
    for res in socket.getaddrinfo(host, port, socket.AF_UNSPEC, socket.SOCK_STREAM):
  File "/usr/lib/python3.7/socket.py", line 752, in getaddrinfo
    for res in _socket.getaddrinfo(host, port, family, type, proto, flags):
socket.gaierror: [Errno -3] Temporary failure in name resolution

During handling of the above exception, another exception occurred:

Traceback (most recent call last):
  File "/opt/lnetd/inputs/nornir/mutils.py", line 55, in get_cards_jnp
    dev.open()
  File "/home/lab/lnetd_env/lib/python3.7/site-packages/jnpr/junos/device.py", line 1396, in open
    raise EzErrors.ConnectUnknownHostError(self)
jnpr.junos.exception.ConnectUnknownHostError: ConnectUnknownHostError(ke-p6-nbi)

During handling of the above exception, another exception occurred:

Traceback (most recent call last):
  File "/home/lab/lnetd_env/lib/python3.7/site-packages/nornir/core/task.py", line 98, in start
    r = self.task(self, **self.params)
  File "/opt/lnetd/inputs/nornir/mutils.py", line 74, in get_cards_jnp
    raise Exception
Exception

2020-12-05 20:09:07,676 - nornir.core.task -    ERROR -      start() - Host 'gb-p10-lon': task 'get_cards_jnp' failed with traceback:
Traceback (most recent call last):
  File "/home/lab/lnetd_env/lib/python3.7/site-packages/jnpr/junos/device.py", line 1360, in open
    "use_filter": self._use_filter,
  File "/home/lab/lnetd_env/lib/python3.7/site-packages/ncclient/manager.py", line 168, in connect
    return connect_ssh(*args, **kwds)
  File "/home/lab/lnetd_env/lib/python3.7/site-packages/ncclient/manager.py", line 135, in connect_ssh
    session.connect(*args, **kwds)
  File "/home/lab/lnetd_env/lib/python3.7/site-packages/ncclient/transport/ssh.py", line 275, in connect
    for res in socket.getaddrinfo(host, port, socket.AF_UNSPEC, socket.SOCK_STREAM):
  File "/usr/lib/python3.7/socket.py", line 752, in getaddrinfo
    for res in _socket.getaddrinfo(host, port, family, type, proto, flags):
socket.gaierror: [Errno -3] Temporary failure in name resolution

During handling of the above exception, another exception occurred:

Traceback (most recent call last):
  File "/opt/lnetd/inputs/nornir/mutils.py", line 55, in get_cards_jnp
    dev.open()
  File "/home/lab/lnetd_env/lib/python3.7/site-packages/jnpr/junos/device.py", line 1396, in open
    raise EzErrors.ConnectUnknownHostError(self)
jnpr.junos.exception.ConnectUnknownHostError: ConnectUnknownHostError(gb-p10-lon)

During handling of the above exception, another exception occurred:

Traceback (most recent call last):
  File "/home/lab/lnetd_env/lib/python3.7/site-packages/nornir/core/task.py", line 98, in start
    r = self.task(self, **self.params)
  File "/opt/lnetd/inputs/nornir/mutils.py", line 74, in get_cards_jnp
    raise Exception
Exception

2020-12-05 20:09:07,679 - nornir.core.task -    ERROR -      start() - Host 'fr-p7-mrs': task 'get_cards_jnp' failed with traceback:
Traceback (most recent call last):
  File "/home/lab/lnetd_env/lib/python3.7/site-packages/jnpr/junos/device.py", line 1360, in open
    "use_filter": self._use_filter,
  File "/home/lab/lnetd_env/lib/python3.7/site-packages/ncclient/manager.py", line 168, in connect
    return connect_ssh(*args, **kwds)
  File "/home/lab/lnetd_env/lib/python3.7/site-packages/ncclient/manager.py", line 135, in connect_ssh
    session.connect(*args, **kwds)
  File "/home/lab/lnetd_env/lib/python3.7/site-packages/ncclient/transport/ssh.py", line 275, in connect
    for res in socket.getaddrinfo(host, port, socket.AF_UNSPEC, socket.SOCK_STREAM):
  File "/usr/lib/python3.7/socket.py", line 752, in getaddrinfo
    for res in _socket.getaddrinfo(host, port, family, type, proto, flags):
socket.gaierror: [Errno -3] Temporary failure in name resolution

During handling of the above exception, another exception occurred:

Traceback (most recent call last):
  File "/opt/lnetd/inputs/nornir/mutils.py", line 55, in get_cards_jnp
    dev.open()
  File "/home/lab/lnetd_env/lib/python3.7/site-packages/jnpr/junos/device.py", line 1396, in open
    raise EzErrors.ConnectUnknownHostError(self)
jnpr.junos.exception.ConnectUnknownHostError: ConnectUnknownHostError(fr-p7-mrs)

During handling of the above exception, another exception occurred:

Traceback (most recent call last):
  File "/home/lab/lnetd_env/lib/python3.7/site-packages/nornir/core/task.py", line 98, in start
    r = self.task(self, **self.params)
  File "/opt/lnetd/inputs/nornir/mutils.py", line 74, in get_cards_jnp
    raise Exception
Exception

2020-12-05 20:09:07,684 - nornir.core.task -    ERROR -      start() - Host 'ke-pe3-nbi': task 'get_cards_jnp' failed with traceback:
Traceback (most recent call last):
  File "/home/lab/lnetd_env/lib/python3.7/site-packages/jnpr/junos/device.py", line 1360, in open
    "use_filter": self._use_filter,
  File "/home/lab/lnetd_env/lib/python3.7/site-packages/ncclient/manager.py", line 168, in connect
    return connect_ssh(*args, **kwds)
  File "/home/lab/lnetd_env/lib/python3.7/site-packages/ncclient/manager.py", line 135, in connect_ssh
    session.connect(*args, **kwds)
  File "/home/lab/lnetd_env/lib/python3.7/site-packages/ncclient/transport/ssh.py", line 275, in connect
    for res in socket.getaddrinfo(host, port, socket.AF_UNSPEC, socket.SOCK_STREAM):
  File "/usr/lib/python3.7/socket.py", line 752, in getaddrinfo
    for res in _socket.getaddrinfo(host, port, family, type, proto, flags):
socket.gaierror: [Errno -3] Temporary failure in name resolution

During handling of the above exception, another exception occurred:

Traceback (most recent call last):
  File "/opt/lnetd/inputs/nornir/mutils.py", line 55, in get_cards_jnp
    dev.open()
  File "/home/lab/lnetd_env/lib/python3.7/site-packages/jnpr/junos/device.py", line 1396, in open
    raise EzErrors.ConnectUnknownHostError(self)
jnpr.junos.exception.ConnectUnknownHostError: ConnectUnknownHostError(ke-pe3-nbi)

During handling of the above exception, another exception occurred:

Traceback (most recent call last):
  File "/home/lab/lnetd_env/lib/python3.7/site-packages/nornir/core/task.py", line 98, in start
    r = self.task(self, **self.params)
  File "/opt/lnetd/inputs/nornir/mutils.py", line 74, in get_cards_jnp
    raise Exception
Exception

2020-12-05 20:09:07,700 - nornir.core.task -    ERROR -      start() - Host 'ke-pe2-nbi': task 'get_cards_jnp' failed with traceback:
Traceback (most recent call last):
  File "/home/lab/lnetd_env/lib/python3.7/site-packages/jnpr/junos/device.py", line 1360, in open
    "use_filter": self._use_filter,
  File "/home/lab/lnetd_env/lib/python3.7/site-packages/ncclient/manager.py", line 168, in connect
    return connect_ssh(*args, **kwds)
  File "/home/lab/lnetd_env/lib/python3.7/site-packages/ncclient/manager.py", line 135, in connect_ssh
    session.connect(*args, **kwds)
  File "/home/lab/lnetd_env/lib/python3.7/site-packages/ncclient/transport/ssh.py", line 275, in connect
    for res in socket.getaddrinfo(host, port, socket.AF_UNSPEC, socket.SOCK_STREAM):
  File "/usr/lib/python3.7/socket.py", line 752, in getaddrinfo
    for res in _socket.getaddrinfo(host, port, family, type, proto, flags):
socket.gaierror: [Errno -3] Temporary failure in name resolution

During handling of the above exception, another exception occurred:

Traceback (most recent call last):
  File "/opt/lnetd/inputs/nornir/mutils.py", line 55, in get_cards_jnp
    dev.open()
  File "/home/lab/lnetd_env/lib/python3.7/site-packages/jnpr/junos/device.py", line 1396, in open
    raise EzErrors.ConnectUnknownHostError(self)
jnpr.junos.exception.ConnectUnknownHostError: ConnectUnknownHostError(ke-pe2-nbi)

During handling of the above exception, another exception occurred:

Traceback (most recent call last):
  File "/home/lab/lnetd_env/lib/python3.7/site-packages/nornir/core/task.py", line 98, in start
    r = self.task(self, **self.params)
  File "/opt/lnetd/inputs/nornir/mutils.py", line 74, in get_cards_jnp
    raise Exception
Exception

2020-12-05 20:09:07,827 -  nornir.core -  WARNING -        run() - Task 'huawei_multiple' has not been run – 0 hosts selected
2020-12-05 20:11:24,401 -  nornir.core -  WARNING -        run() - Task 'netmiko_send_command' has not been run – 0 hosts selected
2020-12-05 20:11:24,460 -  nornir.core -     INFO -        run() - Running task 'get_cards_jnp' with args {'severity_level': 20} on 7 hosts
2020-12-05 20:11:26,199 -  nornir.core -  WARNING -        run() - Task 'huawei_multiple' has not been run – 0 hosts selected
2020-12-05 20:11:52,592 -  nornir.core -     INFO -        run() - Running task 'collect_ping_results' with args {'remote_ip': ['10.5.10.5', '10.8.10.8', '10.177.77.7', '10.7.10.7']} on 1 hosts
2020-12-05 20:11:52,594 -  nornir.core -     INFO -        run() - Running task 'collect_ping_results' with args {'remote_ip': ['10.5.8.5', '10.8.10.10']} on 1 hosts
2020-12-05 20:11:52,607 -  nornir.core -     INFO -        run() - Running task 'collect_ping_results' with args {'remote_ip': ['10.5.10.10', '10.5.8.8']} on 1 hosts
2020-12-05 20:11:52,610 -  nornir.core -     INFO -        run() - Running task 'collect_ping_results' with args {'remote_ip': ['10.2.6.2', '10.6.7.7']} on 1 hosts
2020-12-05 20:11:52,611 -  nornir.core -     INFO -        run() - Running task 'collect_ping_results' with args {'remote_ip': ['10.6.7.6', '10.177.77.10', '10.7.10.10']} on 1 hosts
2020-12-05 20:11:52,615 -  nornir.core -     INFO -        run() - Running task 'collect_ping_results' with args {'remote_ip': ['10.2.6.6', '10.22.33.33', '10.2.3.3']} on 1 hosts
2020-12-05 20:11:52,622 -  nornir.core -     INFO -        run() - Running task 'collect_ping_results' with args {'remote_ip': ['10.22.33.22', '10.2.3.2']} on 1 hosts
2020-12-05 20:12:47,164 -  nornir.core -     INFO -        run() - Running task 'collect_ping_results' with args {'remote_ip': ['10.5.10.5', '10.8.10.8', '10.177.77.7', '10.7.10.7']} on 1 hosts
2020-12-05 20:12:47,165 -  nornir.core -     INFO -        run() - Running task 'collect_ping_results' with args {'remote_ip': ['10.5.8.5', '10.8.10.10']} on 1 hosts
2020-12-05 20:12:47,181 -  nornir.core -     INFO -        run() - Running task 'collect_ping_results' with args {'remote_ip': ['10.5.10.10', '10.5.8.8']} on 1 hosts
2020-12-05 20:12:47,181 -  nornir.core -     INFO -        run() - Running task 'collect_ping_results' with args {'remote_ip': ['10.6.7.6', '10.177.77.10', '10.7.10.10']} on 1 hosts
2020-12-05 20:12:47,187 -  nornir.core -     INFO -        run() - Running task 'collect_ping_results' with args {'remote_ip': ['10.2.6.6', '10.22.33.33', '10.2.3.3']} on 1 hosts
2020-12-05 20:12:47,182 -  nornir.core -     INFO -        run() - Running task 'collect_ping_results' with args {'remote_ip': ['10.2.6.2', '10.6.7.7']} on 1 hosts
2020-12-05 20:12:47,195 -  nornir.core -     INFO -        run() - Running task 'collect_ping_results' with args {'remote_ip': ['10.22.33.22', '10.2.3.2']} on 1 hosts
2020-12-05 20:13:31,208 -  nornir.core -     INFO -        run() - Running task 'collect_ping_results' with args {'remote_ip': ['10.5.10.5', '10.8.10.8', '10.177.77.7', '10.7.10.7']} on 1 hosts
2020-12-05 20:13:31,213 -  nornir.core -     INFO -        run() - Running task 'collect_ping_results' with args {'remote_ip': ['10.5.8.5', '10.8.10.10']} on 1 hosts
2020-12-05 20:13:31,224 -  nornir.core -     INFO -        run() - Running task 'collect_ping_results' with args {'remote_ip': ['10.6.7.6', '10.177.77.10', '10.7.10.10']} on 1 hosts
2020-12-05 20:13:31,229 -  nornir.core -     INFO -        run() - Running task 'collect_ping_results' with args {'remote_ip': ['10.5.10.10', '10.5.8.8']} on 1 hosts
2020-12-05 20:13:31,230 -  nornir.core -     INFO -        run() - Running task 'collect_ping_results' with args {'remote_ip': ['10.2.6.6', '10.22.33.33', '10.2.3.3']} on 1 hosts
2020-12-05 20:13:31,230 -  nornir.core -     INFO -        run() - Running task 'collect_ping_results' with args {'remote_ip': ['10.2.6.2', '10.6.7.7']} on 1 hosts
2020-12-05 20:13:31,232 -  nornir.core -     INFO -        run() - Running task 'collect_ping_results' with args {'remote_ip': ['10.22.33.22', '10.2.3.2']} on 1 hosts
2020-12-05 20:14:09,794 -  nornir.core -  WARNING -        run() - Task 'netmiko_send_command' has not been run – 0 hosts selected
2020-12-05 20:14:09,843 -  nornir.core -  WARNING -        run() - Task 'napalm_get' has not been run – 0 hosts selected
2020-12-05 20:14:09,887 -  nornir.core -  WARNING -        run() - Task 'napalm_get' has not been run – 0 hosts selected
2020-12-05 20:14:09,931 -  nornir.core -  WARNING -        run() - Task 'collect_xr_multiple' has not been run – 0 hosts selected
2020-12-05 20:14:09,975 -  nornir.core -     INFO -        run() - Running task 'napalm_get' with args {'getters': ['facts'], 'severity_level': 20} on 7 hosts
